Workbook
Name \: #REF!
Name \: #REF!
Name \0: #REF!
Name \0: #REF!
Name \a: #N/A
Name \a: #N/A
Name \c: #N/A
Name \F: #REF!
Name \F: #REF!
Name \l: [1]Cover!#REF!
Name \l: [1]Cover!#REF!
Name \l: [1]Cover!#REF!
Name \l: [1]Cover!#REF!
Name \M: #REF!
Name \M: #REF!
Name \M: #REF!
Name \M: #REF!
Name \P: #REF!
Name \P: #REF!
Name \P: #REF!
Name \P: #REF!
Name \q: #N/A
Name \S: #REF!
Name \S: #REF!
Name \S: #REF!
Name \S: #REF!
Name \W: #REF!
Name \W: #REF!
Name \W: #REF!
Name \W: #REF!
Name \WQ: '[2]BAG-2'!#REF!
Name \WQ: '[2]BAG-2'!#REF!
Name \WQ: '[2]BAG-2'!#REF!
Name \WQ: '[2]BAG-2'!#REF!
Name \x: [3]Cover!#REF!
Name \x: [3]Cover!#REF!
Name \x: [3]Cover!#REF!
Name \x: [3]Cover!#REF!
Name __?___RIGHT__?_: #REF!
Name __?___RIGHT__?_: #REF!
Name _______________DIV1: #REF!
Name _______________DIV1: #REF!
Name _______________DIV10: #REF!
Name _______________DIV2: #REF!
Name _______________DIV3: #REF!
Name _______________DIV4: #REF!
Name _______________DIV5: #REF!
Name _______________DIV6: #REF!
Name _______________DIV7: #REF!
Name _______________DIV8: #REF!
Name _______________DIV9: #REF!
Name _______________HAL1: #REF!
Name _______________HAL2: #REF!
Name ______________DIV1: #REF!
Name ______________DIV1: #REF!
Name ______________DIV10: #REF!
Name ______________DIV2: #REF!
Name ______________DIV3: #REF!
Name ______________DIV4: #REF!
Name ______________DIV5: #REF!

Sheet jadwal
B1: JADWAL PENGADAAN LANGSUNG TP SATKER PPSR TA 2025
B3: Satker | D3: : | E3: Satuan Kerja Pelaksanaan Prasarana Strategis Riau
B4: Pekerjaan | D4: : | E4: Konsultan Individual Team Leader
B5: Nilai Pagu | D5: : | E5: 47700000
B6: Nilai HPS | D6: : | E6: =E5 -> 47700000
B8: NO. | C8: URAIAN KEGIATAN | F8: PENOMORAN | G8: HK | H8: TANGGAL/HARI | I8: TANGGAL | J8: KET
B12: 1 | C12: UNDANGAN PENGADAAN LANGSUNG/DOKUMEN PENGADAAN | F12: 01.01/UND/PBJ/KI-PRC/TL/PPK/PPS-RIAU/IV/2025 | G12: 1 hr | H12: 8 April 2025 | I12: Jumat
B13: =B12+1 -> 2 | C13: PEMBERIAN PENJELASAN | F13: 02.01/BA-AAN/PBJ/KI-PRC/TL/PPK/PPS-RIAU/IV/2025 | G13: 1 hr | H13: 9 April 2025 | I13: Kamis
B14: =B13+1 -> 3 | C14: PEMASUKAN DOKUMEN PENAWARAN | G14: 1 hr | H14: 9 April 2025 | I14: Selasa - Kamis
B15: =B14+1 -> 4 | C15: PEMBUKAAN DOKUMEN PENAWARAN & KOREKSI ARITMATIK | F15: 03.01/BUKA-TWR/PBJ/KI-PRC/TL/PPK/PPS-RIAU/IV/2025 | G15: 1 hr | H15: 10 April 2025 | I15: Kamis
B16: =B15+1 -> 5 | C16: EVALUASI PENAWARAN & BA. EVALUASI TEKNIS & BIAYA | F16: 04.01/BA-EVA-TWR/PBJ/KI-PRC/TL/PPK/PPS-RIAU/IV/2025 | G16: 1 hr | H16: 10 April 2025 | I16: Kamis - Senin
B17: =B16+1 -> 6 | C17: EVALUASI KUALIFIKASI & BA HASIL EVALUASI KUALIFIKASI | F17: 05.01/BA-EVA-KUA/PJB/KI-PRC/TL/PPK/PPS-RIAU/IV/2025 | G17: 1 hr | H17: 10 April 2025 | I17: Senin - Selasa
B18: =B17+1 -> 7 | C18: BA HASIL EVALUASI AKHIR | F18: 08.01/BA-EVA/PJB/KI-PRC/TL/PPK/PPS-RIAU/IV/2025 | G18: 1 hr | H18: 10 April 2025 | I18: Kamis
B19: =B18+1 -> 8 | C19: PENETAPAN PENYEDIA JASA | F19: 09.01/TAP/PJB/KI-PRC/TL/PPK/PPS-RIAU/IV/2025 | G19: 1 hr | H19: 10 April 2025 | I19: Jumat
B20: =B19+1 -> 9 | C20: PENGUMUMAN PENYEDIA JASA | F20: 10.01/UMUM/PJB/KI-PRC/TL/PPK/PPS-RIAU/IV/2025 | G20: 1 hr | H20: 10 April 2025 | I20: Senin
B21: =B20+1 -> 10 | C21: UNDANGAN KLARIFIKASI TEKNIS DAN NEGOSIASI BIAYA | F21: 11.01/UND-KLARI-NEGO/PJB/KI-PRC/TL/PPK/PPS-RIAU/IV/2025 | G21: 1 hr | H21: 11 April 2025 | I21: Selasa
B22: =B21+1 -> 11 | C22: BA KLARIFIKASI TEKNIS DAN NEGOSIASI BIAYA | F22: 12.01/BA-KLARI-NEGO/PJB/KI-PRC/TL/PPK/PPS-RIAU/IV/2025 | G22: 1 hr | H22: 11 April 2025 | I22: Rabu
B23: =B22+1 -> 12 | C23: PEMBUATAN BAHP | F23: 13.01/BAHP/PJB/KI-PRC/TL/PPK/PPS-RIAU/IV/2025 | G23: 1 hr | H23: 11 April 2025 | I23: Kamis
B24: =B23+1 -> 13 | C24: BA SERAH TERIMA DOKUMEN | F24: 14.01/BAHP/PJB/KI-PRC/TL/PPK/PPS-RIAU/IV/2025 | G24: 1 hr | H24: 14 April 2025 | I24: Kamis
B25: =B24+1 -> 14 | C25: PENUNJUKAN PENYEDIA JASA KONSULTANSI | F25: PB.01/SPPBJ/01/KI-PRC/TL/PPK/PPS-RIAU/IV2025 | G25: 1 hr | H25: 15 April 2025 | I25: Jumat
B26: =B25+1 -> 15 | C26: PENANDATANGAN KONTRAK | F26: HK.02.03/SPK/KI-PRC.01/TL/04/2025 | G26: 1 hr | H26: 15 April 2025 | I26: Senin

Sheet UNDANGAN
A7: Nomor | C7: : | D7: =jadwal!F12 -> 01.01/UND/PBJ/KI-PRC/TL/PPK/PPS-RIAU/IV/2025 | G7: Pekanbaru, 8 April 2025
A8: Lampiran | C8: : | D8: 1 (satu) berkas
A10: Kepada Yth.
A11: Ade Putra. ST.
A12: Di,
B13: Tempat
A15: Perihal | C15: : | D15: Undangan Penawaran Pengadaan Pekerjaan
D16: Konsultan Individual Team Leader
A18: Dalam rangka memenuhi kebutuhan Satuan Kerja Pelaksanaan Prasarana Strategis Riau, dalam kegiatan Dokumentasi dan Publikasi dengan ini mengundang Saudara untuk mengikuti Pengadaan Konsultan Individual Team Leader Sumber Dana APBN Tahun Anggaran 2025.
A22: Apabila Saudara berminat agar mengajukan penawaran harga dan ditujukan kepada Pejabat Pengadaan Barang dan Jasa Pada Satuan Kerja Pelaksanaan Prasarana Strategis Riau dengan melampirkan persyaratan permohonan dan lampiran sebagai berikut :
A25: 1 | B25: Surat Penawaran
A26: 2 | B26: RAB dan Rekapitulasi Penawaran
A27: 3 | B27: Dokumen Kualifikasi yang telah diisi
A28: 4 | B28: Curriculum Vitae
A29: 5 | B29: Ijazah dan Transkrip Nilai
A30: 6 | B30: KTP dan NPWP yang masih berlaku
A31: 7 | B31: Serifikat Keahliaan (Jika ada)
A33: Demikian undangan ini disampaikan, atas perhatiannya diucapkan terima kasih.
E35: Pejabat Pengadaan Barang/Jasa Pemerintah Pada Satuan Kerja Pelaksanaan Prasarana Strategis
E38: KASDIONO, ST
E39: NIP. 19720101 200701 1 008

Sheet 2_BA_Pemb_Twr
B2: PEJABAT PENGADAAN BARANG/JASA PEMERINTAH
B3: PADA SATUAN KERJA PELAKSANAAN PRASARANA STRATEGIS RIAU
B4: TAHUN ANGGARAN 2025
B8: SATUAN KERJA | H8: BERITA ACARA PEMBUKAAN PENAWARAN
B9: Pelaksanaan Prasarana Strategis Riau
B11: Pekerjaan :
B12: =UNDANGAN!D16 -> Konsultan Individual Team Leader | H12: Nomor | I12: : | J12: =jadwal!F15 -> 03.01/BUKA-TWR/PBJ/KI-PRC/TL/PPK/PPS-RIAU/IV/2025
H13: Tanggal | I13: : | J13: =jadwal!H15 -> 10 April 2025
H14: HPS | I14: : | J14: ='1. Lam Pemb twr'!E11 -> 47700000
B15: Lokasi : | H15: Lampiran | I15: : | J15: 1 (satu) Berkas
B16: Provinsi Riau
B19: Pada hari ini Kamis tanggal Sepuluh bulan April tahun Dua Ribu Dua Puluh Lima, Pejabat Pemeriksa Hasil Pekerjaan Pengadaan Barang dan Jasa di Lingkungan Satuan Kerja Pelaksanaan Prasarana Strategis Riau Tahun Anggaran 2025 yang diangkat sesuai dengan Surat Keputusan Kepala Satuan Kerja Pelaksanaan Prasarana Strategis Riau, No : 01/KPTS/PBJ/SATKER/PPS-RIAU/2025 Tanggal 27 Maret 2025. mengambil tempat Ruang Satuan Kerja Pelaksanaan Prasarana Strategis Riau Jalan Bakti Ruko Komplek Perumahan Mutiara Asri Garden Pekanbaru, telah mengadakan rapat Pembukaan Penawaran pekerjaan tersebut diatas dengan ini menyatakan bahwa :
B27: 1. | C27: a. | D27: Tenaga penyedia perorangan yang mendaftar untuk mengikuti pelelangan ini sebanyak | L27: : 1 (Satu) orang.
C28: b. | D28: Memasukkan dokumen penawaran (Administrasi, Teknis, Harga) sebanyak | L28: : 1 (Satu) orang.
B30: 2. | C30: Setelah dilakukan Penelitian dokumen penawaran (Administrasi, Teknis dan Harga), ternyata :
C31: a. | D31: Yang lengkap sebanyak | L31: : 1 (Satu) orang.
C32: b. | D32: Yang tidak lengkap sebanyak | L32: : 0 (Nol) orang.
B34: 3. | C34: Berdasarkan hasil pembukaan penawaran tersebut diatas, maka dilanjutkan ke tahap berikutnya.
B36: Demikian Berita Acara Pembukaan Penawaran ini dibuat dengan sebenarnya untuk dapat dipergunakan seperlunya.
J39: =UNDANGAN!E35 -> Pejabat Pengadaan Barang/Jasa Pemerintah Pada Satuan Kerja Pelaksanaan Prasarana Strategis
J46: =UNDANGAN!E38 -> KASDIONO, ST
J47: =UNDANGAN!E39 -> NIP. 19720101 200701 1 008

Sheet 1. Lam Pemb twr
F2: Lampiran | G2: : | H2: Pembukaan Administrasi, Teknis dan Biaya
F3: Nomor | G3: : | H3: =jadwal!F15 -> 03.01/BUKA-TWR/PBJ/KI-PRC/TL/PPK/PPS-RIAU/IV/2025
F4: Tanggal | G4: : | H4: =jadwal!H15 -> 10 April 2025
B6: LAMPIRAN PEMBUKAAN DOKUMEN PENAWARAN
B8: Pekerjaan | D8: : | E8: =UNDANGAN!D16 -> Konsultan Individual Team Leader
B9: Lokasi | D9: : | E9: ='2_BA_Pemb_Twr'!B16 -> Provinsi Riau
B10: Pagu Dana | D10: : | E10: 47700000
B11: HPS | D11: : | E11: =E10 -> 47700000
B13: No | C13: NAMA TENAGA PENDUKUNG | F13: SURAT PENAWARAN | G13: DOKUMEN PENAWARAN BIAYA | I13: DOKUMEN PQ | J13: KETERANGAN
B17: 1 | C17: 2 | F17: 3 | G17: 4 | I17: 5 | J17: 6
B19: 1 | C19: =UNDANGAN!A11 -> Ade Putra. ST. | F19: A | H19: A | I19: A | J19: =IF(AND(F19="A",H19="A"),"LENGKAP","TIDAK LENGKAP") -> LENGKAP
B22: Catatan :
B23: A | C23: = ADA
B24: TA | C24: = TIDAK ADA | H24: =UNDANGAN!E35 -> Pejabat Pengadaan Barang/Jasa Pemerintah Pada Satuan Kerja Pelaksanaan Prasarana Strategis
H31: =UNDANGAN!E38 -> KASDIONO, ST
H32: =UNDANGAN!E39 -> NIP. 19720101 200701 1 008

Sheet 3. EVA - ADM
K2: Lampiran : | L2: BA HASIL EVALUASI ADM, TEKNIS & BIAYA
K3: Nomor : | L3: =jadwal!F16 -> 04.01/BA-EVA-TWR/PBJ/KI-PRC/TL/PPK/PPS-RIAU/IV/2025
K4: Tanggal : | L4: =jadwal!H16 -> 10 April 2025
B5: 1. EVALUASI ADMINISTRASI
B7: Satuan Kerja | D7: : | E7: Satuan Kerja Pelaksanaan Prasarana Strategis Riau
B8: Pekerjaan | D8: : | E8: ='1. Lam Pemb twr'!E8 -> Konsultan Individual Team Leader
B9: Lokasi | D9: : | E9: Provinsi Riau
B10: HPS | D10: : | E10: ='1. Lam Pemb twr'!E11 -> 47700000
B11: Tahun Anggaran | D11: : | E11: 2025
B12: Sumber Dana | D12: : | E12: APBN
B15: NO. | C15: Nama Tenaga Pendukung | G15: EVALUASI ADMINISTRASI | O15: KESIMPULAN AKHIR | P15: KETERANGAN
G16: SURAT PENAWARAN
G17: Jangka waktu berlakunya surat penawaran (HK) | I17: Total Penawaran biaya | K17: Jangka waktu pelaksanaan pekerjaan | M17: Tanggal Penawaran
F18: MS / TMS | G18: 60 | H18: MS/TMS | I18: Rp | J18: MS/TMS | K18: 9 Bulan | L18: MS/TMS | M18: A/TA | N18: MS/TMS
B19: 1 | C19: 2 | F19: =#REF!+1 -> #REF! | G19: 3 | H19: =G19+1 -> 4 | I19: 5 | J19: 6 | K19: 7 | L19: 8 | M19: 9 | N19: =M19+1 -> 10 | O19: 11 | P19: =O19+1 -> 12
B21: 1 | C21: ='1. Lam Pemb twr'!C19:E19 -> Ade Putra. ST. | G21: 60 | H21: MS | I21: 47700000 | J21: MS | K21: 9 | L21: MS | M21: A | N21: =IF($M$21="A","MS","TMS") -> MS | O21: MS | P21: Dilanjutkan ke tahap Evaluasi Kualifikasi | S21: SURAT PENAWARAN SESUAI DALAM DOKUMEN PENGADAAN
B24: Keterangan | D24: S : Sesuai TS : Tidak Sesuai MS : Memenuhi Syarat TMS : Tidak Memenuhi Syarat
D25: A : Ada TA : Tidak Ada

Sheet 4. Lamp. TA
B2: LAMPIRAN PENILAIAN KUALIFIKASI TENAGA PENUNJANG
B4: NAMA TENAGA AHLI | F4: : | G4: ='3. EVA - ADM'!C21 -> Ade Putra. ST.
B5: POSISI YANG DIUSULKAN | F5: : | G5: =UNDANGAN!D16 -> Konsultan Individual Team Leader
B7: A. PENDIDIKAN | F7: :
B9: Persyaratan KAK | H9: Ijazah Tenaga Pendukung Yang di berikan | M9: Penilaian | P9: NILAI
B10: S1 Desain Komunikasi Visual | H10: S1 Desain Komunikasi Visual | N10: S | P10: =IF(N10="S",100,IF(N10="TS",0,)) -> 100
B12: B. PENGALAMAN KERJA PROFESIONAL
B14: NO | C14: NAMA PROYEK | E14: PERIODE | H14: BULAN | J14: LINGKUP | L14: POSISI | N14: REFERENSI PENGALAMAN KERJA TA | P14: JUMLAH
E15: DARI | F15: SAMPAI
B16: 1 | C16: 2 | E16: 2 | H16: 3 | J16: 4 | L16: 5 | N16: 6 | P16: 7
B18: 2 | E18: 01 Januari 2022 | G18: 44926 | H18: 12 | J18: S | K18: =IF(J18="S",100%,IF(J18="M",50%,)) -> 1 | L18: S | M18: =IF(L18="S",100%,IF(L18="TS",50%,)) -> 1 | N18: A | O18: =IF(N18="A",1,IF(N18="TA",0,)) -> 1 | P18: =M18*K18*H18*O18 -> 12
B19: =B18+1 -> 3 | E19: 01 Januari 2023 | G19: 31 Desember 2018 | H19: 12 | J19: S | K19: =IF(J19="S",100%,IF(J19="M",50%,)) -> 1 | L19: S | M19: =IF(L19="S",100%,IF(L19="TS",50%,)) -> 1 | N19: A | O19: =IF(N19="A",1,IF(N19="TA",0,)) -> 1 | P19: =M19*K19*H19*O19 -> 12
B20: =B19+1 -> 4 | E20: 45292 | G20: 43830 | H20: 12 | J20: S | K20: =IF(J20="S",100%,IF(J20="M",50%,)) -> 1 | L20: S | M20: =IF(L20="S",100%,IF(L20="TS",50%,)) -> 1 | N20: A | O20: =IF(N20="A",1,IF(N20="TA",0,)) -> 1 | P20: =M20*K20*H20*O20 -> 12
B21: 5 | E21: 45658 | G21: 44196 | H21: 12 | J21: S | K21: =IF(J21="S",100%,IF(J21="M",50%,)) -> 1 | L21: S | M21: =IF(L21="S",100%,IF(L21="TS",50%,)) -> 1 | N21: A | O21: =IF(N21="A",1,IF(N21="TA",0,)) -> 1 | P21: =M21*K21*H21*O21 -> 12
B23: PERSYARATAN KAK | F23: 3 | O23: Total Bln = | P23: =SUM(P18:P22) -> 48
O24: Total Thn = | P24: =P23/12 -> 4
O25: NILAI PENGALAMAN TENAGA PENDUKUNG | P25: =IF(P24>=F23,100,IF(P24>1.5,75,IF(P24<F23,50))) -> 100 | T25: TOTAL PENGALAMAN KURANG DARI 3 TAHUN SEGERA DIPERBAIKI SERTA REFERENSI DARI PENGGUNA JASA
B26: Ketentuan pengalaman kerja pada KAK :
B27: Pendidikan S1 memiliki pengalaman sekurang-kurangnya 3 Tahun Kerja
B29: C. SERTIKAT KEAHLIAN/ PROFESI
B30: Persyaratan KAK | H30: SKA Tenaga Ahli Yang di berikan | M30: Penilaian | P30: NILAI
B31: SKA Muda | H31: SKA Madya | N31: Ada | P31: =IF(N31="Ada",100,IF(N31="Tidak Ada",0,)) -> 100
B33: D. SUB UNSUR LAIN-LAIN
B34: D1. Penguasaan bahasa asing | M34: Penilaian | P34: NILAI
N35: Tidak Ada | P35: =IF(N35="Ada",100,IF(N35="Tidak Ada",0)) -> 0
B36: D2. Penguasaan bahasa setempat | M36: Penilaian | P36: NILAI
N37: Ada | P37: =IF(N37="Ada",100,IF(N37="Tidak Ada",0)) -> 100
B38: D3. penguasaan Bahasa Indonesia bagi konsultan asing | M38: Penilaian | P38: NILAI
N39: Tidak Ada | P39: =IF(N39="Ada",100,IF(N39="Tidak Ada",0)) -> 0
B40: D4. aspek pengenalan (familiarity) atas tata-cara, aturan, situasi, dan kondisi (custom) setempat | M40: Penilaian | P40: NILAI
N41: Tidak Ada | P41: =IF(N41="Ada",100,IF(N41="Tidak Ada",0)) -> 0
B43: NO | E43: URAIAN HASIL PENILAIAN TENAGA AHLI | M43: NILAI | N43: BOBOT | O43: NILAI X BOBOT
B44: A | E44: PENDIDIKAN | M44: =P10 -> 100 | N44: 0.3 | P44: =M44*N44 -> 30
B45: B | E45: PENGALAMAN KERJA PROFESINAL | M45: =P25 -> 100 | N45: 0.5 | P45: =M45*N45 -> 50
B46: C | E46: SERTIFIKAT KEAHLIAN/ PROFESI | M46: =P31 -> 100 | N46: 0.15 | P46: =M46*N46 -> 15
B47: D | E47: SUB UNSUR LAIN-LAIN | S47: 0.05
B48: D1 | E48: Penguasaan bahasa asing | M48: =P35 -> 0 | N48: 0.0125 | P48: =M48*N48 -> 0
B49: D2 | E49: Penguasaan bahasa setempat | M49: =P37 -> 100 | N49: 0.0125 | P49: =M49*N49 -> 1.25
B50: D3 | E50: penguasaan Bahasa Indonesia bagi konsultan asing | M50: =P39 -> 0 | N50: 0.0125 | P50: =M50*N50 -> 0
B51: D4 | E51: aspek pengenalan (familiarity) atas tata-cara, aturan, situasi, dan kondisi (custom) setempat | M51: =P41 -> 0 | N51: 0.0125 | P51: =M51*N51 -> 0 | S51: =2.5/2 -> 1.25
...

Sheet 5. Teknis
V2: ='3. EVA - ADM'!K2 -> Lampiran : | W2: ='3. EVA - ADM'!L2 -> BA HASIL EVALUASI ADM, TEKNIS & BIAYA
V3: ='3. EVA - ADM'!K3 -> Nomor : | W3: ='3. EVA - ADM'!L3 -> 04.01/BA-EVA-TWR/PBJ/KI-PRC/TL/PPK/PPS-RIAU/IV/2025
V4: ='3. EVA - ADM'!K4 -> Tanggal : | W4: ='3. EVA - ADM'!L4 -> 10 April 2025
C7: 2. EVALUASI TEKNIS
C9: ='3. EVA - ADM'!B7 -> Satuan Kerja | O9: ='9. Kualifikasi'!D4 -> : | P9: ='3. EVA - ADM'!E7 -> Satuan Kerja Pelaksanaan Prasarana Strategis Riau
C10: ='3. EVA - ADM'!B8 -> Pekerjaan | O10: ='9. Kualifikasi'!D5 -> : | P10: ='3. EVA - ADM'!E8 -> Konsultan Individual Team Leader
C11: ='3. EVA - ADM'!B9 -> Lokasi | O11: ='9. Kualifikasi'!D6 -> : | P11: ='3. EVA - ADM'!E9 -> Provinsi Riau
C12: ='3. EVA - ADM'!#REF! -> #REF! | O12: ='9. Kualifikasi'!D7 -> : | P12: ='3. EVA - ADM'!#REF! -> #REF!
C13: ='3. EVA - ADM'!B10 -> HPS | O13: ='9. Kualifikasi'!D8 -> : | P13: ='3. EVA - ADM'!E10 -> 47700000
C14: ='3. EVA - ADM'!B11 -> Tahun Anggaran | O14: ='9. Kualifikasi'!D9 -> : | P14: 2025
C15: ='3. EVA - ADM'!B12 -> Sumber Dana | O15: ='9. Kualifikasi'!D10 -> : | P15: ='3. EVA - ADM'!E12 -> APBN
B18: No | C18: Nama Tenaga Ahli | D18: Pendekatan dan Metodologi 20% | N18: Total Pendekatan dan Metodologi 20% | O18: Kualifikasi Tenaga Ahli 100% | Z18: TOTAL kualifikasi tenaga ahli 100% | AA18: total keseluruhan | AB18: passing grade 70 | AC18: Ket | AF18: Pemahaman Terhadap KAK | AM18: Tingkat Pendidikan
D19: Pemahaman Terhadap KAK | F19: Kualitas Metodologi | H19: Hasil Kerja | J19: Fasilitas Pendukung | L19: Gagasan Baru | O19: tingkat pendidikan | Q19: pengalaman kerja | S19: Sertifikat Keahlian Profesi | T19: Nilai | U19: lain-lain | Y19: Nilai | AF19: 10 | AG19: 100 | AH19: ADA | AM19: 10 | AN19: 100
U20: 0.05 | AF20: 5 | AG20: 50 | AH20: KURANG | AM20: 5 | AN20: 50
U21: ='4. Lamp. TA'!E48 -> Penguasaan bahasa asing | V21: ='4. Lamp. TA'!E49 -> Penguasaan bahasa setempat | W21: ='4. Lamp. TA'!E50 -> penguasaan Bahasa Indonesia bagi konsultan asing | X21: ='4. Lamp. TA'!E51 -> aspek pengenalan (familiarity) atas tata-cara, aturan, situasi, dan kondisi (custom) setempat
S22: 0.15
D23: Bobot | E23: Nilai | F23: Bobot | G23: Nilai | H23: Bobot | I23: Nilai | J23: Bobot | K23: Nilai | L23: Bobot | M23: Nilai | O23: Bobot | P23: Nilai | Q23: Bobot | R23: Nilai | S23: Memiliki=100
D24: 0.4 | F24: 0.2 | H24: 0.2 | J24: 0.1 | L24: 0.1 | O24: 0.5 | Q24: 0.5
S25: Tidak Memiliki=0
B28: 1 | C28: 2 | D28: 3 | E28: 4 | F28: 5 | G28: 6 | H28: 7 | I28: 8 | J28: 9 | K28: 10 | L28: 11 | M28: 12 | N28: 13 | O28: 3 | P28: 4 | Q28: 5 | R28: 6 | S28: 7 | T28: 8 | U28: 9 | V28: 10 | W28: 11 | X28: 12 | Y28: 13 | Z28: 14 | AA28: 15 | AB28: 16 | AC28: 17 | AF28: 0 | AG28: 0 | AH28: TDK ADA
B30: 1 | C30: ='3. EVA - ADM'!C21 -> Ade Putra. ST. | D30: 80 | E30: =D30*$D$24 -> 32 | F30: 80 | G30: =F30*$F$24 -> 16 | H30: 80 | I30: =H30*$H$24 -> 16 | J30: 80 | K30: =J30*$J$24 -> 8 | L30: 80 | M30: =L30*$L$24 -> 8 | N30: =(M30+K30+I30+G30+E30)*20% -> 16 | O30: 85 | P30: =O30*O24 -> 42.5 | Q30: 78 | R30: =Q30*$Q$24 -> 39 | S30: 100 | T30: 14 | V30: 25 | W30: 25 | X30: 26 | Y30: =(U30+V30+W30+X30)*5% -> 3.8 | Z30: =(Y30+T30+R30+P30)*100% -> 99.3 | AA30: =Z30 -> 99.3 | AB30: =IF(AA30>=70,"MS","TMS") -> MS | AM30: Pengalaman Kerja
B33: Keterangan : | D33: MS : Memenuhi Syarat TMS : Tidak Memenuhi Syarat | O33: MS : | P33: Memenuhi Syarat | S33: TMS : | T33: Tidak Memenuhi Syarat | AF33: Hasil Kerja | AM33: refrensi
AF34: 5 | AG34: 50 | AM34: 5 | AN34: 50
AF36: Fasilitas Pendukung | AM36: a | AN36: 30 | AP36: tidak bisa
S50: KELOMPOK KERJA SATKER PERENCANAAN DAN PENGENDALIAN PROGRAM INFRASTRUKTUR PERMUKIMAN PROVINSI RIAU TAHUN ANGGARAN 2016

Sheet 12. EVA - BIAYA
M2: ='5. Teknis'!V2 -> Lampiran : | N2: ='5. Teknis'!W2 -> BA HASIL EVALUASI ADM, TEKNIS & BIAYA
M3: ='5. Teknis'!V3 -> Nomor : | N3: =jadwal!F16 -> 04.01/BA-EVA-TWR/PBJ/KI-PRC/TL/PPK/PPS-RIAU/IV/2025
M4: ='5. Teknis'!V4 -> Tanggal : | N4: ='5. Teknis'!W4 -> 10 April 2025
B6: 3. EVALUASI HARGA
B8: ='5. Teknis'!C9 -> Satuan Kerja | D8: : | E8: ='5. Teknis'!P9 -> Satuan Kerja Pelaksanaan Prasarana Strategis Riau
B9: ='5. Teknis'!C10 -> Pekerjaan | D9: : | E9: ='5. Teknis'!P10 -> Konsultan Individual Team Leader
B10: ='5. Teknis'!C11 -> Lokasi | D10: : | E10: ='5. Teknis'!P11 -> Provinsi Riau
B11: Pagu | D11: : | E11: =E12 -> 47700000
B12: ='5. Teknis'!C13 -> HPS | D12: : | E12: ='5. Teknis'!P13 -> 47700000
B13: ='5. Teknis'!C14 -> Tahun Anggaran | D13: : | E13: ='5. Teknis'!P14 -> 2025
B14: ='5. Teknis'!C15 -> Sumber Dana | D14: : | E14: ='5. Teknis'!P15 -> APBN
B17: No | C17: Nama Tenaga Pendukung | G17: Daftar Rekapitulasi Biaya | I17: Harga Penawaran | M17: Harga Penawaran Terkoreksi | Q17: Nilai Akhir | R17: Keterangan
G18: A / TA | H18: MS/TMS | I18: Rp. | J18: MS/TMS | M18: Rp. | N18: MS/TMS
B19: 1 | C19: =B19+1 -> 2 | G19: =C19+1 -> 3 | H19: =G19+1 -> 4 | I19: =H19+1 -> 5 | J19: =I19+1 -> 6 | M19: 7 | N19: 8 | Q19: 9 | R19: 10
B21: 1 | C21: ='5. Teknis'!C30 -> Ade Putra. ST. | G21: A | H21: =IF(G21="A","MS","TMS") -> MS | I21: 47700000 | J21: =IF(I21<=$E$11,"=HPS","> HPS") -> =HPS | K21: : | L21: =IF(I21<=$E$11,"MS","TMS") -> MS | M21: =I21 -> 47700000 | N21: =IF(M21<=$E$11,"= HPS","> HPS") -> = HPS | O21: : | P21: =IF(M21<=$E$11,"MS","TMS") -> MS | Q21: MS | R21: Dilanjutkan ke tahap Evaluasi Kualifikasi
C24: Keterangan | F24: A : Ada TA : Tidak Ada MS : Memenuhi Syarat TMS : Tidak Memenuhi Syarat

Sheet 7. Aritmatik
E2: KOREKSI ARITMATIK
B4: Satuan Kerja | D4: : | E4: ='12. EVA - BIAYA'!E8 -> Satuan Kerja Pelaksanaan Prasarana Strategis Riau
B5: Pekerjaan | D5: : | E5: ='1. Lam Pemb twr'!E8 -> Konsultan Individual Team Leader
B6: Lokasi | D6: : | E6: Provinsi Riau
B7: HPS | D7: : | E7: ='1. Lam Pemb twr'!E11 -> 47700000
B8: Tahun Anggaran | D8: : | E8: ='12. EVA - BIAYA'!E13:F13 -> 2025
B9: Sumber Dana | D9: : | E9: APBN
B11: NAMA | D11: : | E11: Ade Putra. ST.
B13: No. | C13: Uraian | G13: Hasil Harga Penawaran | H13: Harga Terkoreksi
G14: RP | H14: RP
B15: 1 | C15: 2 | G15: 3 | H15: 4.
B17: A | C17: ='6. Aritmatik Ade P'!C8 -> BIAYA LANGSUNG PERSONIL | G17: 45016000 | H17: =G17 -> 45016000
B18: B | C18: ='6. Aritmatik Ade P'!C20 -> BIAYA LANGSUNG NON PERSONIL | G18: 2714000 | H18: =G18 -> 2714000
C20: Jumlah | E20: TOTAL A + B | G20: =SUM(G17:G19) -> 47730000 | H20: =SUM(H17:H19) -> 47730000
E21: DIBULATKAN | G21: 47700000 | H21: =G21 -> 47700000

Sheet 6. Aritmatik Ade P
B2: KOREKSI ARITMATIK
B3: TENAGA PENUNJANG PEMANTAUAN DAN EVALUASI
B4: SATUAN KERJA PELAKSANAN PRASARANA STRATEGIS RIAU
B6: I | C6: ='1. Lam Pemb twr'!C19:E19 -> Ade Putra. ST.
B8: A. | C8: BIAYA LANGSUNG PERSONIL | D8: HPS | H8: PENAWARAN | L8: KOREKSI ARITMATIK
B9: No | C9: Uraian Kegiatan | D9: Satuan | E9: Volume | F9: Harga Satuan (Rp) | G9: Jumlah (Rp) | H9: Satuan | I9: Volume | J9: Harga Satuan (Rp) | K9: Jumlah (Rp) | L9: Satuan | M9: Volume | N9: Harga Satuan (Rp) | O9: Jumlah (Rp)
B12: I | C12: TENAGA AHLI
B14: 1 | C14: =UNDANGAN!D16 -> Konsultan Individual Team Leader | D14: OB | E14: 3 | F14: 15195000 | G14: =E14*F14 -> 45585000 | H14: OB | I14: 3 | J14: =F14 -> 15195000 | K14: =I14*J14 -> 45585000 | L14: =H14 -> OB | M14: =I14 -> 3 | N14: =J14 -> 15195000 | O14: =K14 -> 45585000
C17: TOTAL A | G17: =SUM(G14) -> 45585000 | K17: =+K14 -> 45585000 | O17: =+O14 -> 45585000 | R17: =G17 -> 45585000 | S17: =K17 -> 45585000 | T17: =O17 -> 45585000
B20: B. | C20: BIAYA LANGSUNG NON PERSONIL
B21: NO | C21: URAIAN KEGIATAN | D21: Satuan | E21: Volume | F21: Harga Satuan (Rp) | G21: Jumlah (Rp) | H21: Satuan | I21: Volume | J21: Harga Satuan (Rp) | K21: Jumlah (Rp) | L21: Satuan | M21: Volume | N21: Harga Satuan (Rp) | O21: Jumlah (Rp)
B25: 1 | C25: Biaya Pembuatan Laporan
B26: - | C26: Laporan Bulanan | D26: BUKU | E26: 21 | F26: 62000 | G26: =E26*F26 -> 1302000 | H26: BUKU | I26: =E26 -> 21 | J26: 62000 | K26: =J26*I26 -> 1302000 | L26: =H26 -> BUKU | M26: =I26 -> 21 | N26: =J26 -> 62000 | O26: =N26*M26 -> 1302000
C27: Laporan Koordinasi (Pendampingan & Fasilitasi) | D27: BUKU | E27: 6 | F27: 80000 | G27: 480000 | H27: BUKU | I27: =E27 -> 6 | J27: 80000 | K27: 480000 | L27: =H27 -> BUKU | M27: =I27 -> 6 | N27: =J27 -> 80000 | O27: 480000
I28: =E28 -> 0
B29: - | C29: Laporan Akhir | D29: BUKU | E29: 3 | F29: 120000 | G29: 360000 | H29: BUKU | I29: =E29 -> 3 | J29: 120000 | K29: 360000 | L29: BUKU | M29: =I29 -> 3 | N29: =J29 -> 120000 | O29: 360000
C31: TOTAL B | G31: =SUM(G26:G29) -> 2142000 | K31: =SUM(K25:K29) -> 2142000 | O31: =SUM(O25:O29) -> 2142000 | R31: =G31 -> 2142000 | S31: =K31 -> 2142000 | T31: =O31 -> 2142000
R32: =SUM(R17:R31) -> 47727000 | S32: =SUM(S17:S31) -> 47727000 | T32: =SUM(T17:T31) -> 47727000

Sheet 8. BA - EVA (AdmTek&biaya)
B2: ='2_BA_Pemb_Twr'!B2:L2 -> PEJABAT PENGADAAN BARANG/JASA PEMERINTAH
B3: ='2_BA_Pemb_Twr'!B3:L3 -> PADA SATUAN KERJA PELAKSANAAN PRASARANA STRATEGIS RIAU
B4: ='2_BA_Pemb_Twr'!B4:L4 -> TAHUN ANGGARAN 2025
S8: TAHAUN ANGGARAN 2015
B9: SATUAN KERJA | H9: BERITA ACARA
B10: SATUAN KERJA PELAKSANAAN PRASARANA STRATEGIS RIAU | H10: EVALUASI ADMINISTRASI DAN TEKNIS
B13: PEKERJAAN
B14: ='2_BA_Pemb_Twr'!B12 -> Konsultan Individual Team Leader | H14: No | I14: : | J14: =jadwal!F16 -> 04.01/BA-EVA-TWR/PBJ/KI-PRC/TL/PPK/PPS-RIAU/IV/2025
H15: Tanggal | I15: : | J15: =jadwal!H16 -> 10 April 2025
B16: LOKASI | H16: HPS | I16: : | J16: ='1. Lam Pemb twr'!E10 -> 47700000
B17: ='2_BA_Pemb_Twr'!B16:G16 -> Provinsi Riau
B20: Pada hari ini Kamis tanggal Sepuluh bulan April tahun Dua Ribu Dua Puluh Lima, yang bertanda tangan dibawah ini, Pejabat Pengadaan Barang/Jasa Pemerintah di Lingkungan Satuan Kerja Pelaksanaan Prasarana Strategis Riau yang diangkat sesuai dengan Surat Keputusan Kepala Satuan Kerja Pelaksanaan Prasarana Strategis Riau, No : 01/KPTS/PBJ/SATKER/PPS-RIAU/2025 Tanggal 27 Maret 2025, telah melaksanakan Evaluasi Administrasi dan Teknis terhadap Tenaga Penunjang yang mengikuti pelelangan Pekerjaan tersebut diatas, dengan uraian sebagai berikut : | R20: 0.05
R21: 9730000000
R22: =R21*R20 -> 486500000
C28: No. | D28: Nama Tenaga Ahli | F28: Rekap Hasil Evaluasi | N28: Hasil Akhir
F29: Harga Penawaran (Rp.) | G29: Harga Terkoreksi (Rp.) | H29: HPS | K29: ADM | L29: Nilai Teknis | M29: Biaya
C30: 1 | D30: 2 | F30: 3 | G30: 4 | H30: 5 | K30: 6 | L30: 7 | M30: 8 | N30: 9
C32: 1 | D32: ='12. EVA - BIAYA'!C21 -> Ade Putra. ST. | F32: ='3. EVA - ADM'!I21 -> 47700000 | G32: =F32 -> 47700000 | H32: = HPS | I32: : | J32: ='[203]BA - EVA (AdmTek&biaya)'!$J$32 -> MS | K32: ='3. EVA - ADM'!O21 -> MS | L32: MS | M32: ='12. EVA - BIAYA'!Q21 -> MS
D35: MS : Memenuhi Syarat
D36: TMS : Tidak Memenuhi Syarat
D37: Evaluasi Administrasi, Teknis dan Biaya secara detail tedapat di lembar lampiran
C40: a. | D40: Jumlah peserta yang mendaftar untuk mengikuti pelelangan ini sebanyak | I40: : | J40: 1 (Satu) Orang
C41: b. | D41: Jumlah peserta mengambil Dokumen Lelang sebanyak | I41: : | J41: 1 (Satu) Orang
C42: c. | D42: Jumlah peserta memasukkan dokumen penawaran sebanyak | I42: : | J42: 1 (Satu) Orang
C44: Berdasarkan hasil Evaluasi diatas, maka Pejabat Pengadaan Barang/Jasa berkesimpulan sebagai berikut :
C46: 1. | D46: Penelitian Adminstrasi | E46: : | F46: Yang memenuhi Syarat | I46: : | J46: 1 (Satu) Orang
F47: Tidak memenuhi Syarat | I47: : | J47: 0 (Nol) Orang
F48: Tidak dievaluasi | I48: : | J48: 0 (Nol) Orang
C50: 2. | D50: Penelitian Teknis | E50: : | F50: Yang memenuhi Syarat | I50: : | J50: 1 (Satu) Orang
F51: Tidak memenuhi Syarat | I51: : | J51: 0 (Nol) Orang
F52: Tidak dievaluasi | I52: : | J52: 0 (Nol) Orang
C54: 3. | D54: Penelitian Biaya | E54: : | F54: Yang memenuhi Syarat | I54: : | J54: 1 (Satu) Orang
F55: Tidak memenuhi Syarat | I55: : | J55: 0 (Nol) Orang
F56: Tidak dievaluasi | I56: : | J56: 0 (Nol) Orang
B58: Demikianlah Berita Acara Evaluasi Penawaran ini dibuat untuk dapat dipergunakan sebagai mana mestinya.
J61: =UNDANGAN!E35 -> Pejabat Pengadaan Barang/Jasa Pemerintah Pada Satuan Kerja Pelaksanaan Prasarana Strategis
J68: =UNDANGAN!E38 -> KASDIONO, ST
J69: =UNDANGAN!E39 -> NIP. 19720101 200701 1 008

Sheet 9. Kualifikasi
B2: EVALUASI KUALIFIKASI
B4: ='12. EVA - BIAYA'!B8 -> Satuan Kerja | D4: : | E4: ='3. EVA - ADM'!E7 -> Satuan Kerja Pelaksanaan Prasarana Strategis Riau
B5: ='12. EVA - BIAYA'!B9 -> Pekerjaan | D5: : | E5: ='3. EVA - ADM'!$E$8 -> Konsultan Individual Team Leader
B6: ='12. EVA - BIAYA'!B10 -> Lokasi | D6: : | E6: Provinsi Riau
B7: ='12. EVA - BIAYA'!B11 -> Pagu | D7: : | E7: ='3. EVA - ADM'!#REF! -> #REF!
B8: ='12. EVA - BIAYA'!B12 -> HPS | D8: : | E8: ='1. Lam Pemb twr'!E11 -> 47700000
B9: ='12. EVA - BIAYA'!B13 -> Tahun Anggaran | D9: : | E9: 2025
B10: ='12. EVA - BIAYA'!B14 -> Sumber Dana | D10: : | E10: APBN
B13: NO | C13: Nama Tenaga Pendukung | E13: Tanda Tangan dan Materai Isian Formulir Kualifikasi | F13: Surat Pernyataan Kesediaan ditugaskan | G13: Pengalaman Pekerjaan dalam 3 Tahun Terakhir | H13: Isian Kualifikasi | N13: Pakta Integritas | O13: Surat Keterangan Kinerja Baik/Surat Referensi Kerja | P13: Foto Copy Ijazah | Q13: Hasil Akhir | R13: Ket
H14: A. Data Administrasi | I14: B. Data Keuangan | K14: C. Data Pengalaman dan Kualifikasi | L14: B. Data Fasilitas/Peralatan/Perlengkapan yang mendukung | M14: C. Data Pekerjaan yang sedang dilaksanakan
I15: SPT 2017 | J15: NPWP
B16: 1 | C16: 2 | E16: =C16+1 -> 3 | F16: 4 | G16: 5 | H16: 6 | I16: 7 | J16: 8 | K16: 9 | L16: 7 | M16: 8 | N16: 9 | O16: 13 | P16: 14 | Q16: 10 | R16: 11
B18: 1 | C18: ='8. BA - EVA (AdmTek&biaya)'!D32 -> Ade Putra. ST. | E18: A | F18: A | G18: A | H18: A | I18: A | J18: A | K18: A | L18: A | M18: A | N18: A | O18: A | P18: A | Q18: =IF(AND(E18="A",G18="A",H18="A",I18="A",K18="A",L18="A",M18="A",O18="A",P18="A"),"MS","TMS") -> MS | U18: SEMUA LAMPIRAN PRAKUALIFIKASI HARUS DILAMPIRKAN
B21: Keterangan: | U21: 15.633.066.4-216.000 | X21: Jl. Selamat Gg. Makmur No. 1 Labuh Baru Pekanbaru
C22: A : Ada | E22: MS : Memenuhi Syarat | U22: 78.653.205.1-216.000 | X22: Jln Aur Kuning No. 23 RT.03 RW 03 Simpang Tiga Pekanbaru-Riau
C23: TA : Tidak Ada | E23: TMS : Tidak Memenuhi Syarat | U23: 15.671.715.9-216.000 | X23: Jln Kartama Perum Kartama Cluster C 6 Marpoyan Damai Pekanbaru-Riau
U24: 25.202.426.0-652.000 | X24: Jl. Pembangunan No. 55 B Pekanbaru
U25: 14.498.419.2-204.000 | X25: Jalan Raya Batusangkar – Payakumbuh Km.25 No.78 Barulak, Kec. Tanjung Baru, Kab.Tanah Datar, Sumatera Barat (27262)
U26: 14.640.568.3-219.000 | X26: Jl. Firdaus I No. 15 A Tangkerang Labuai Pekanbaru

Sheet 11. Und pembuktian
B2: PEJABAT PENGADAAN BARANG/JASA
B3: PADA SATUAN KERJA PERENCANAAN DAN PENGENDALIAN
B4: PROGRAM INFRASTRUKTUR PERMUKIMAN
B5: TAHUN ANGGARAN 2018
B9: Nomor | C9: : | D9: =jadwal!#REF! -> #REF! | H9: Pekanbaru, | J9: =jadwal!#REF! -> #REF!
B10: Lampiran | C10: : | D10: -
B11: Perihal | C11: : | D11: Undangan Pembuktian Kualifikasi | H11: Kepada Yth Sdr.
H12: ='9. Kualifikasi'!C18 -> Ade Putra. ST.
H14: (Tidak boleh diwakilkan)
H15: di -
I16: Tempat
C18: Dengan Hormat,
C20: Berdasarkan Berita Acara Evaluasi Kualifikasi Nomor : 05.3/BA-EVA-KUA/PJB/KI-TEKNIS/RANDAL/APBN/ I/2018 Tanggal 23 Januari 2018 untuk pekerjaan Konsultan Individual Pemantauan dan Evaluasi, Sumber Dana APBN Tahun Anggaran 2018, maka sesuai dengan Peraturan Presiden No. 54 Tahun 2010, Peraturan Presiden No. 70 Tahun 2012, dokumen pengadaan serta addendum dokumen pengadaan, maka setiap Dokumen Penawaran yang memenuhi persyaratan dokumen lelang dilakukan pembuktian kualifikasi terhadap dokumen penawaran yang saudara sampaikan.
C28: Berkenaan dengan hal tersebut bersama ini kami mengundang saudara untuk hadir :
D30: Hari | E30: : | F30: Rabu
D31: Tanggal | E31: : | F31: 24 Januari 2018
D32: Waktu | E32: : | F32: 09:00 WIB s.d. 14.00 WIB
D33: Tempat | E33: : | F33: Ruang PPK Randal Riau Gedung PIP2B
D34: Alamat | E34: : | F34: Jl. Arifin Ahmad Pekanbaru
C36: Apabila saudara tidak dapat hadir sesuai dengan jadwal tersebut diatas serta tidak dapat memperlihatkan data asli sesuai dengan dokumen kualifikasi, maka saudara dinyatakan gugur serta tidak Memenuhi Syarat untuk memasukan dokumen penawaran.
C41: Demikian kami sampaikan atas kehadiran saudara diucapkan terima kasih.
H44: Pejabat Pengadaan Barang/Jasa,
H49: S U J O K O, ST
H50: NIP. 19680323 199703 1 002
D52: Catatan :
D53: Agar membawa materai Rp. 6000,- sebanyak 1 (satu) buah.

Sheet 12. BA - Pembuktian
B2: ='11. Und pembuktian'!B2:N2 -> PEJABAT PENGADAAN BARANG/JASA
B3: ='11. Und pembuktian'!B3:N3 -> PADA SATUAN KERJA PERENCANAAN DAN PENGENDALIAN
B4: ='11. Und pembuktian'!B4:N4 -> PROGRAM INFRASTRUKTUR PERMUKIMAN
B5: ='11. Und pembuktian'!B5:N5 -> TAHUN ANGGARAN 2018
B10: ='14. BA - EVA'!B8 -> SATUAN KERJA | G10: BERITA ACARA
B11: ='9. Kualifikasi'!E4 -> Satuan Kerja Pelaksanaan Prasarana Strategis Riau | G11: PEMBUKTIAN KUALIFIKASI
B14: PEKERJAAN
B15: ='13. REKAP EVA'!E8 -> Konsultan Individual Team Leader | G15: No | H15: : | I15: =jadwal!#REF! -> #REF!
G16: Tanggal | H16: : | I16: 24 Januari 2018
B17: LOKASI | G17: HPS | H17: : | I17: ='9. Kualifikasi'!E8 -> 47700000
B18: ='13. REKAP EVA'!E9 -> Provinsi Riau
B21: Pada hari ini Rabu, tanggal Dua puluh empat bulan Januari tahun Dua ribu delapan belas, yang bertanda tangan dibawah ini, Pejabat Pengadaan Barang/Jasa Pada Satker Perencanaan Dan Pengendalian Program Infrastruktur Permukiman Tahun Anggaran 2018 yang diangkat sesuai dengan Surat Keputusan Kepala Satker Perencanaan Dan Pengendalian Program Infrastruktur Permukiman, No : 06/KPTS/Cp/RDL/2018 tanggal 05 Januari 2018, mengambil tempat Ruang PPK Randal Riau Gedung PIP2B Jl. Arifin Ahmad Pekanbaru, telah melakukan pembuktian kualifikasi kepada peserta :
C29: Nama Konsultan Perorangan | E29: : | F29: ='9. Kualifikasi'!C18 -> Ade Putra. ST.
C30: Alamat | E30: : | F30: Jl. Setia Budi No. 27, Desa Harapan Duri
C31: NPWP | E31: : | F31: 72.907.750.3-219.000
C32: Nilai Teknis | E32: : | F32: ='8. BA - EVA (AdmTek&biaya)'!L32 -> MS
C33: Harga Penawaran | E33: : | F33: ='8. BA - EVA (AdmTek&biaya)'!F32 -> 47700000
C34: Harga Penawaran Terkoreksi | E34: : | F34: ='8. BA - EVA (AdmTek&biaya)'!G32 -> 47700000
C35: ='[204]BA - EVA'!D102 -> Waktu Pelaksanaan | E35: : | F35: 11 (Sebelas) bulan
C37: 1 | D37: (Dapat / Tidak Dapat) memperlihatkan Asli Surat Penawaran.
C38: 2 | D38: (Dapat / Tidak Dapat) memperlihatkan Asli Surat Pernyataan Kesedian Ditugaskan
C39: 3 | D39: (Dapat / Tidak Dapat) memperlihatkan Asli Usulan Teknis
C40: 4 | D40: (Dapat / Tidak Dapat) memperlihatkan Asli Jadwal Pelaksanaan
C41: 5 | D41: (Dapat / Tidak Dapat) memperlihatkan Asli Daftar Rekapitukasi Harga Penawaran Biaya
C42: 6 | D42: (Dapat / Tidak Dapat) memperlihatkan Asli Ijazah Terakhir
C43: 7 | D43: (Dapat / Tidak Dapat) memperlihatkan Asli NPWP
C44: 8 | D44: (Dapat / Tidak Dapat) memperlihatkan Asli SPT Tahun 2016
C45: 9 | D45: (Dapat / Tidak Dapat) memperlihatkan Pengalaman Pekerjaan dalam 4 tahun terakhir
C46: 10 | D46: (Dapat / Tidak Dapat) memperlihatkan Asli Identitas (KTP/SIM)
C49: Setelah dilakukan Pembuktian Kualifikasi terhadap data kualifikasi maka Pejabat Pengadaan berkesimpulan saudara | M49: =F29 -> Ade Putra. ST.
C50: (Dapat / Tidak Dapat) memasukan dokumen penawaran.
C51: Catatan :
C55: Demikianlah Berita Acara Pembuktian Kualifikasi ini dibuat untuk dapat dipergunakan sebagaimana mestinya.
C58: Konsultan Perorangan | K58: Pejabat Pengadaan Barang/Jasa,
C62: Materai
C63: Rp. 6000,-
C66: =M49 -> Ade Putra. ST. | K66: S U J O K O, ST
K67: NIP. 19680323 199703 1 002

Sheet 10. BA - Kualifikasi
B2: PEJABAT PENGADAAN BARANG/JASA
B3: PADA SATUAN KERJA PERENCANAAN DAN PENGENDALIAN
B4: PROGRAM INFRASTRUKTUR PERMUKIMAN
B5: TAHUN ANGGARAN 2018
B10: SATKER | H10: BERITA ACARA
B11: ='12. BA - Pembuktian'!B11 -> Satuan Kerja Pelaksanaan Prasarana Strategis Riau | H11: HASIL EVALUASI KUALIFIKASI
B14: PEKERJAAN
B15: ='12. BA - Pembuktian'!B15 -> Konsultan Individual Team Leader | H15: No | I15: : | J15: =jadwal!F17 -> 05.01/BA-EVA-KUA/PJB/KI-PRC/TL/PPK/PPS-RIAU/IV/2025
H16: Tanggal | I16: : | J16: 23 Januari 2018
B17: LOKASI | H17: HPS | I17: : | J17: 49500000
B18: ='3. EVA - ADM'!E9 -> Provinsi Riau
B21: Pada hari ini Selasa, tanggal Dua puluh tiga bulan Januari tahun Dua ribu delapan belas, yang bertanda tangan dibawah ini, Pejabat Pengadaan Barang/Jasa Pada Satker Perencanaan dan Pengendalian Program Infrastruktur Permukiman Tahun Anggaran 2018 yang diangkat sesuai dengan Surat Keputusan Kepala Satker Perencanaan dan Pengendalian Program Infrastruktur Permukiman, No : 06/KPTS/Cp/RDL/2018 tanggal 05 Januari 2018, telah melaksanakan Evaluasi Kualifikasi terhadap Konsultan Perorangan yang mengikuti pelelangan Pekerjaan tersebut diatas, dengan uraian sebagai berikut :
D29: No. | E29: Nama Tenaga Ahli | G29: Rekap Evaluasi Kualifikasi | I29: Keterangan
G30: Evaluasi Kualifikasi
D31: 1 | E31: 2 | G31: 3 | I31: 4
D33: 1 | E33: ='9. Kualifikasi'!C18 -> Ade Putra. ST. | G33: ='9. Kualifikasi'!Q18 -> MS | I33: TMS
E36: MS : Memenuhi Syarat
E37: TMS : Tidak Memenuhi Syarat
E38: Evaluasi Kualifikasi dan pembuktian Kualifikasi secara detail tedapat di lembar lampiran
C42: a. | D42: Jumlah peserta yang mendaftar untuk mengikuti lelang sebanyak | I42: : | J42: ='8. BA - EVA (AdmTek&biaya)'!J40 -> 1 (Satu) Orang
C43: b. | D43: Jumlah peserta mengambil Dokumen Lelang sebanyak | I43: : | J43: ='8. BA - EVA (AdmTek&biaya)'!J41 -> 1 (Satu) Orang
C44: c. | D44: Jumlah peserta memasukkan dokumen penawaran sebanyak | I44: : | J44: ='8. BA - EVA (AdmTek&biaya)'!J42 -> 1 (Satu) Orang
C46: Berdasarkan hasil Evaluasi diatas, maka Pejabat Pengadaan berkesimpulan sebagai berikut :
C48: 1. | D48: Penelitian Dokumen Kualifikasi | F48: : | G48: Yang memenuhi Syarat | I48: : | J48: ='[205]8. BA - EVA (AdmTek&biaya)'!J47 -> 1 (Satu) Orang
G49: Tidak memenuhi Syarat | I49: : | J49: ='[205]8. BA - EVA (AdmTek&biaya)'!J48 -> 0 (Nol) Orang
G50: Tidak dievaluasi | I50: : | J50: ='[205]8. BA - EVA (AdmTek&biaya)'!J49 -> 0 (Nol) Orang
C52: 2. | D52: Pembuktian Kualifikasi | F52: : | G52: Diundang | I52: : | J52: ='[205]8. BA - EVA (AdmTek&biaya)'!J51 -> 1 (Satu) Orang
G53: Tidak diundang | I53: : | J53: ='[205]8. BA - EVA (AdmTek&biaya)'!J52 -> 0 (Nol) Orang
G54: Yang memenuhi Syarat | I54: : | J54: ='[205]8. BA - EVA (AdmTek&biaya)'!J53 -> 0 (Nol) Orang
B57: Demikianlah Berita Acara Evaluasi Kualifikasi ini dibuat untuk dapat dipergunakan sebagai mana mestinya.
J60: Pejabat Pengadaan Barang/Jasa,
J65: S U J O K O, ST
J66: NIP. 19680323 199703 1 002

Sheet 14. BA - EVA
B2: ='8. BA - EVA (AdmTek&biaya)'!B2:N2 -> PEJABAT PENGADAAN BARANG/JASA PEMERINTAH
B3: ='8. BA - EVA (AdmTek&biaya)'!B3:N3 -> PADA SATUAN KERJA PELAKSANAAN PRASARANA STRATEGIS RIAU
B4: ='8. BA - EVA (AdmTek&biaya)'!B4:N4 -> TAHUN ANGGARAN 2025
B8: SATUAN KERJA | H8: BERITA ACARA
B9: ='2_BA_Pemb_Twr'!B9:G9 -> Pelaksanaan Prasarana Strategis Riau | H9: HASIL EVALUASI
B12: PEKERJAAN
B13: ='12. EVA - BIAYA'!E9 -> Konsultan Individual Team Leader | H13: No | I13: : | J13: =jadwal!F18 -> 08.01/BA-EVA/PJB/KI-PRC/TL/PPK/PPS-RIAU/IV/2025
H14: Tanggal | I14: : | J14: =jadwal!H18 -> 10 April 2025
B15: LOKASI | H15: HPS | I15: : | J15: ='8. BA - EVA (AdmTek&biaya)'!J16 -> 47700000
B16: ='3. EVA - ADM'!E9 -> Provinsi Riau
B18: Pada hari ini Kamis tanggal Sepuluh bulan April tahun Dua Ribu Dua Puluh Lima, yang bertanda tangan dibawah ini, Pejabat Pemeriksa Hasil Pekerjaan Pengadaan Barang dan Jasa Di Lingkungan Satuan Kerja Pelaksanaan Prasarana Strategis Riau Tahun Anggaran 2025 yang diangkat sesuai dengan Surat Keputusan Kepala Satuan Kerja Pelaksanaan Prasarana Strategis Riau, No : 01/KPTS/PBJ/SATKER/PPS-RIAU/2025 Tanggal 27 Maret 2025, telah melaksanakan Evaluasi terhadap Tenaga Perorangan yang mengikuti pengadaan Langsung Pekerjaan tersebut diatas, dengan uraian sebagai berikut :
C25: No. | D25: Nama Tenaga Ahli | F25: Rekap Hasil Evaluasi | O25: Hasil Akhir
F26: Harga Penawaran (Rp.) | G26: Harga Terkoreksi (Rp.) | H26: HPS | K26: ADM | L26: Nilai Teknis PS = 65 | M26: Biaya | N26: Kualifikasi
C27: 1 | D27: 2 | F27: 3 | G27: 4 | H27: 5 | K27: 6 | L27: 7 | M27: 8 | N27: 9. | O27: 9
C29: 1 | D29: ='13. REKAP EVA'!C19 -> Ade Putra. ST. | F29: ='8. BA - EVA (AdmTek&biaya)'!F32 -> 47700000 | G29: =F29 -> 47700000 | H29: ='[203]REKAP EVA'!I19 -> < HPS | I29: : | J29: ='[203]REKAP EVA'!K19 -> MS | K29: ='13. REKAP EVA'!K19 -> MS | L29: ='13. REKAP EVA'!L19 -> MS | M29: ='13. REKAP EVA'!M19 -> MS | N29: ='9. Kualifikasi'!Q18 -> MS | O29: Lulus
D32: MS : Memenuhi Syarat
D33: TMS : Tidak Memenuhi Syarat
D34: Evaluasi Administrasi, Teknis , Biaya dan Biaya secara detail tedapat di lembar lampiran
C37: a. | D37: Jumlah peserta yang mendaftar untuk mengikuti pelelangan ini sebanyak | I37: : | J37: 1 (Satu) Orang
C38: b. | D38: Jumlah peserta mengambil Dokumen Lelang sebanyak | I38: : | J38: 1 (Satu) Orang
C39: c. | D39: Jumlah peserta memasukkan dokumen penawaran sebanyak | I39: : | J39: 1 (Satu) Orang
C41: Berdasarkan hasil Evaluasi diatas, maka Pejabat Pengadaan berkesimpulan sebagai berikut :
C43: 1. | D43: Penelitian Adminstrasi | E43: : | F43: Yang memenuhi Syarat | I43: : | J43: 1 (Satu) Orang
F44: Tidak memenuhi Syarat | I44: : | J44: 0 (Nol) Orang
F45: Tidak dievaluasi | I45: : | J45: 0 (Nol) Orang
C47: 2. | D47: Penelitian Teknis | E47: : | F47: Yang memenuhi Syarat | I47: : | J47: 1 (Satu) Orang
F48: Tidak memenuhi Syarat | I48: : | J48: 0 (Nol) Orang
F49: Tidak dievaluasi | I49: : | J49: 0 (Nol) Orang
C51: 3. | D51: Penelitian Biaya | E51: : | F51: Yang memenuhi Syarat | I51: : | J51: 1 (Satu) Orang
F52: Tidak memenuhi Syarat | I52: : | J52: 0 (Nol) Orang
F53: Tidak dievaluasi | I53: : | J53: 0 (Nol) Orang
C55: 4. | D55: Penelitian Dokumen Kualifikasi | E55: : | F55: Yang memenuhi Syarat | I55: : | J55: 1 (Satu) Orang
F56: Tidak memenuhi Syarat | I56: : | J56: 0 (Nol) Orang
F57: Tidak dievaluasi | I57: : | J57: 0 (Nol) Orang
C59: 5. | D59: Pembuktian Kualifikasi | E59: : | F59: Yang memenuhi Syarat | I59: : | J59: 1 (Satu) Orang
F60: Tidak memenuhi Syarat | I60: : | J60: 0 (Nol) Orang
F61: Tidak dievaluasi | I61: : | J61: 0 (Nol) Orang
C63: Berdasarkan hasil Evaluasi diatas, maka Pokja berkesimpulan untuk mengusulkan konsultan perorangan dibawah ini sebagai calon pemenang Pekerjaan tersebut di atas, sebagai berikut :
C66: Calon Pemenang
D67: Nama Tenaga Pendukung | E67: : | F67: ='12. BA - Pembuktian'!F29 -> Ade Putra. ST.
...

Sheet 13. REKAP EVA
K2: Lampiran : | L2: BA HASIL EVALUASI ADM, TEKNIS & BIAYA dan KUALIFIKASI
K3: Nomor : | L3: =jadwal!F18 -> 08.01/BA-EVA/PJB/KI-PRC/TL/PPK/PPS-RIAU/IV/2025
K4: Tanggal : | L4: =jadwal!H18 -> 10 April 2025
B6: REKAP HASIL EVALUASI
B7: ='12. EVA - BIAYA'!B8 -> Satuan Kerja | D7: : | E7: ='12. EVA - BIAYA'!E8 -> Satuan Kerja Pelaksanaan Prasarana Strategis Riau
B8: ='12. EVA - BIAYA'!B9 -> Pekerjaan | D8: : | E8: ='12. EVA - BIAYA'!E9 -> Konsultan Individual Team Leader
B9: ='12. EVA - BIAYA'!B10 -> Lokasi | D9: : | E9: ='12. EVA - BIAYA'!E10 -> Provinsi Riau
B10: ='12. EVA - BIAYA'!B11 -> Pagu | D10: : | E10: ='12. EVA - BIAYA'!E11 -> 47700000 | O10: `
B11: ='12. EVA - BIAYA'!B12 -> HPS | D11: : | E11: ='3. EVA - ADM'!E10 -> 47700000
B12: ='12. EVA - BIAYA'!B13 -> Tahun Anggaran | D12: : | E12: ='12. EVA - BIAYA'!E13 -> 2025
B13: ='12. EVA - BIAYA'!B14 -> Sumber Dana | D13: : | E13: ='12. EVA - BIAYA'!E14 -> APBN
B15: No. | C15: Nama Tenaga Ahli | E15: Hasil Evaluasi | O15: Hasil Akhir | P15: Keterangan
E16: Harga Penawaran (Rp.) | F16: Harga Terkoreksi (Rp.) | G16: % HPS | H16: HPS | K16: ADM | L16: Nilai Teknis PS = 65 | M16: Biaya | N16: Kualifikasi
B17: 1 | C17: 2 | E17: 3 | F17: 4 | G17: 5 | H17: 6 | K17: 7 | L17: 8 | M17: 9 | N17: 10 | O17: 11 | P17: 12
B19: 1 | C19: ='10. BA - Kualifikasi'!E33 -> Ade Putra. ST. | E19: ='14. BA - EVA'!F29 -> 47700000 | F19: =E19 -> 47700000 | G19: =(F19/$E$11)*100 -> 100 | H19: =IF(E19<=$E$11,"= HPS","> HPS") -> = HPS | I19: : | J19: =IF(F19<=$E$9,"MS","TMS") -> MS | K19: ='8. BA - EVA (AdmTek&biaya)'!K32 -> MS | L19: ='8. BA - EVA (AdmTek&biaya)'!L32 -> MS | M19: ='8. BA - EVA (AdmTek&biaya)'!M32 -> MS | N19: ='10. BA - Kualifikasi'!G33 -> MS | O19: =IF(AND(J19="MS",K19="MS",L19>=65,M19="MS",N19="MS"),"LULUS","GUGUR") -> LULUS
C22: Keterangan :
C23: MS : Memenuhi Syarat | G23: TMS : Tidak Memenuhi Syarat

Sheet 15Penetapan
B2: PEJABAT PENGADAAN BARANG/JASA PEMERINTAH
B3: ='19. BAHP'!B3:M3 -> PADA SATUAN KERJA PELAKSANAAN PRASARANA STRATEGIS RIAU
B4: TAHUN ANGGARAN 2025
B8: Nomor | C8: : | D8: =jadwal!F19 -> 09.01/TAP/PJB/KI-PRC/TL/PPK/PPS-RIAU/IV/2025 | K8: Pekanbaru, | L8: =jadwal!H19 -> 10 April 2025
B9: Lampiran | C9: : | D9: 1 (Satu) Berkas
B10: Perihal | C10: : | D10: Penetapan Pemenang
C14: Berdasarkan Berita Acara Hasil Evaluasi Nomor : 08.01/BA-EVA/PJB/KI-PRC/TL/PPK/PPS-RIAU/IV/2025 tanggal 10 April 2025 beserta dokumen pendukungnya, dengan ini kami tetapkan pemenang Jasa Konsultansi Perorangan Pekerjaan Konsultan Individual Team Leader Sumber dana APBN Tahun Anggaran 2025, sebagai berikut :
C19: Pemenang
D20: Nama Ttenaga Pendukung | E20: : | F20: ='14. BA - EVA'!F67 -> Ade Putra. ST.
D21: Alamat | E21: : | F21: ='14. BA - EVA'!F69 -> Jl. Berdikari Perum. Puri Alam Permai Blok A-6 Tenayan Raya Pekanbaru
D22: NPWP | E22: : | F22: ='14. BA - EVA'!F68 -> 75.198.282.8-212.000
D23: Harga Penawaran | E23: : | F23: ='14. BA - EVA'!F70 -> 47700000
D24: harga Penawaran Terkoreksi | E24: : | F24: ='14. BA - EVA'!F71 -> 47700000
D25: Waktu Pelaksanaan | E25: : | F25: ='14. BA - EVA'!F72 -> 3 (Tiga) Bulan
C27: Demikian Penetapan Pemenang Pengadaan Jasa Tenaga Perorangan, sumber Dana APBN Tahun Anggaran 2025 untuk diketahui dan dilaksanakan sebagaimana mestinya.
H31: =UNDANGAN!E35 -> Pejabat Pengadaan Barang/Jasa Pemerintah Pada Satuan Kerja Pelaksanaan Prasarana Strategis
H38: =UNDANGAN!E38 -> KASDIONO, ST
H39: =UNDANGAN!E39 -> NIP. 19720101 200701 1 008

Sheet 16. pengumuman
B2: ='15Penetapan'!B2:M2 -> PEJABAT PENGADAAN BARANG/JASA PEMERINTAH
B3: ='15Penetapan'!B3:M3 -> PADA SATUAN KERJA PELAKSANAAN PRASARANA STRATEGIS RIAU
B4: ='15Penetapan'!B4:M4 -> TAHUN ANGGARAN 2025
A7: PENGUMUMAN PEMENANG
B8: =jadwal!F20 -> 10.01/UMUM/PJB/KI-PRC/TL/PPK/PPS-RIAU/IV/2025
B11: Berdasarkan Penetapan Pemenang Nomor : 09.01/TAP/PJB/KI-PRC/TL/PPK/PPS-RIAU/IV/2025 Tanggal 10 April 2025, Pengadaan Pekerjaan Tenaga Penunjang Konsultan Individual Team Leader, Sumber Dana APBN Tahun Anggaran 2025.
B15: Dengan ini disampaikan kepada peserta seleksi untuk pekerjaan tersebut diatas sebagai pemenang dalam seleksi adalah saudara yang tersebut dibawah ini :
B18: Pemenang
C19: ='15Penetapan'!D20 -> Nama Ttenaga Pendukung | D19: : | E19: ='15Penetapan'!F20 -> Ade Putra. ST.
C20: ='15Penetapan'!D21 -> Alamat | D20: =[206]PEN!E33 -> : | E20: ='15Penetapan'!F21 -> Jl. Berdikari Perum. Puri Alam Permai Blok A-6 Tenayan Raya Pekanbaru
C21: ='15Penetapan'!D22 -> NPWP | D21: =[206]PEN!E34 -> : | E21: ='15Penetapan'!F22 -> 75.198.282.8-212.000
C22: ='15Penetapan'!D23 -> Harga Penawaran | D22: =[206]PEN!E35 -> : | E22: ='15Penetapan'!F23 -> 47700000
C23: ='15Penetapan'!D24 -> harga Penawaran Terkoreksi | D23: =[206]PEN!E36 -> : | E23: ='15Penetapan'!F24 -> 47700000
C24: ='15Penetapan'!D25 -> Waktu Pelaksanaan | D24: =[206]PEN!E37 -> : | E24: ='15Penetapan'!F25 -> 3 (Tiga) Bulan
C26: Untuk melaksanakan pekerjaan tersebut sesuai dengan syarat-syarat yang telah ditentukan dalam dokumen pengadaan beserta addendum dokumen pengadaan, sebagai Pemenang Cadangan dengan syarat-syarat yang sama dengan pemenang Pertama ditetapkan.
B31: Kepada Saudara yang telah mengikuti pelelangan tersebut atas partisipasinya kami ucapkan terima kasih.
H35: Pekanbaru, 10 April 2025
H37: =UNDANGAN!E35 -> Pejabat Pengadaan Barang/Jasa Pemerintah Pada Satuan Kerja Pelaksanaan Prasarana Strategis
H43: =UNDANGAN!E38 -> KASDIONO, ST
H44: =UNDANGAN!E39 -> NIP. 19720101 200701 1 008

Sheet 17. UND-Klari-Nego
B1: ='14. BA - EVA'!B2:O2 -> PEJABAT PENGADAAN BARANG/JASA PEMERINTAH
B2: ='14. BA - EVA'!B3:O3 -> PADA SATUAN KERJA PELAKSANAAN PRASARANA STRATEGIS RIAU
B4: ='14. BA - EVA'!B4:O4 -> TAHUN ANGGARAN 2025
B8: Nomor | C8: : | D8: =jadwal!F21 -> 11.01/UND-KLARI-NEGO/PJB/KI-PRC/TL/PPK/PPS-RIAU/IV/2025 | I8: Pekanbaru, | J8: =jadwal!H21 -> 11 April 2025
B9: Lampiran | C9: :
B11: Kepada Yth. Sdr;
B12: ='16. pengumuman'!E19 -> Ade Putra. ST.
B13: ='16. pengumuman'!E20 -> Jl. Berdikari Perum. Puri Alam Permai Blok A-6 Tenayan Raya Pekanbaru
B14: (Tidak bisa diwakilkan)
B15: Di –
B16: Tempat
B19: Perihal | C19: : | D19: Undangan Klarifikasi dan Negosiasi
B22: Dengan hormat,
B24: Berdasarkan Pengumuman Pemenang Nomor : 10.4/UMUM/PJB/KI-TEKNIS/RANDAL/APBN/I/2018 tanggal 29 Januari 2018, Konsultan Individual Pemantauan dan Evaluasi dengan sumber Pembiayaan APBN Tahun Anggaran 2018 dengan ini mengundang Saudara untuk dapat hadir pada :
B29: Hari/Tanggal | C29: : | D29: Rabu / 31 Januari 2018
B30: Pukul | C30: : | D30: 09.00 s/d 16.00 WIB
B31: Tempat | C31: : | D31: Ruang PPK Randal Riau Gedung PIP2B Jl. Arifin Achmad Pekanbaru
B32: Acara | C32: : | D32: Klarifikasi dan Negosiasi
B34: Demikianlah undangan ini disampaikan, atas kehadiran Saudara tepat pada waktunya diucapkan terima kasih.
G37: Pejabat Pengadaan Barang/Jasa,
G46: S U J O K O, ST
G47: NIP. 19680323 199703 1 002

Sheet 18. Nego Arit Didi
B2: HASIL NEGOSIASI
B3: KONSULTAN INDIVIDUAL PEMANTAUAN DAN EVALUASI
B5: I | C5: ='3. EVA - ADM'!C21 -> Ade Putra. ST.
B7: A. | C7: BIAYA LANGSUNG PERSONIL | D7: HPS | H7: KOREKSI ARITMATIK | L7: HARGA NEGOSIASI
B8: No | C8: Uraian Kegiatan | D8: Satuan | E8: Volume | F8: Harga Satuan (Rp) | G8: Jumlah (Rp) | H8: Satuan | I8: Volume | J8: Harga Satuan (Rp) | K8: Jumlah (Rp) | L8: Satuan | M8: Volume | N8: Harga Satuan (Rp) | O8: Jumlah (Rp)
B11: I | C11: TENAGA AHLI
B13: 1 | C13: ='6. Aritmatik Ade P'!C14 -> Konsultan Individual Team Leader | D13: ='6. Aritmatik Ade P'!D14 -> OB | E13: ='6. Aritmatik Ade P'!E14 -> 3 | F13: ='6. Aritmatik Ade P'!F14 -> 15195000 | G13: =D13*E13*F13 -> #VALUE! | H13: =D13 -> OB | I13: =E13 -> 3 | J13: ='6. Aritmatik Ade P'!N14 -> 15195000 | K13: =H13*I13*J13 -> #VALUE! | L13: =H13 -> OB | M13: =I13 -> 3 | N13: =J13 -> 15195000 | O13: =L13*M13*N13 -> #VALUE!
C16: TOTAL A | G16: =SUM(G13:G15) -> #VALUE! | K16: =SUM(K13:K15) -> #VALUE! | O16: =SUM(O13:O14) -> #VALUE!
B19: B. | C19: BIAYA LANGSUNG NON PERSONIL
B20: No | C20: Uraian Kegiatan | D20: Satuan | E20: Volume | F20: Harga Satuan (Rp) | G20: Jumlah (Rp) | H20: Satuan | I20: Volume | J20: Harga Satuan (Rp) | K20: Jumlah (Rp) | L20: Satuan | M20: Volume | N20: Harga Satuan (Rp) | O20: Jumlah (Rp)
B24: 1 | C24: Biaya Pembuatan Laporan
C25: Laporan Bulanan | D25: ='6. Aritmatik Ade P'!D26 -> BUKU | E25: ='6. Aritmatik Ade P'!E26 -> 21 | F25: ='6. Aritmatik Ade P'!F26 -> 62000 | G25: =D25*E25*F25 -> #VALUE! | H25: =D25 -> BUKU | I25: =E25 -> 21 | J25: ='6. Aritmatik Ade P'!N26 -> 62000 | K25: =H25*I25*J25 -> #VALUE! | L25: =H25 -> BUKU | M25: =I25 -> 21 | N25: =F25 -> 62000 | O25: =L25*M25*N25 -> #VALUE!
C26: Laporan Koordinasi (Pendampingan & Fasilitasi) | D26: ='6. Aritmatik Ade P'!D27 -> BUKU | E26: ='6. Aritmatik Ade P'!E27 -> 6 | F26: ='6. Aritmatik Ade P'!F27 -> 80000 | G26: =D26*E26*F26 -> #VALUE! | H26: =D26 -> BUKU | I26: =E26 -> 6 | J26: ='6. Aritmatik Ade P'!N27 -> 80000 | K26: =H26*I26*J26 -> #VALUE! | L26: =H26 -> BUKU | M26: =I26 -> 6 | N26: =J26 -> 80000 | O26: =L26*M26*N26 -> #VALUE!
C28: Laporan Akhir | D28: ='6. Aritmatik Ade P'!D29 -> BUKU | E28: ='6. Aritmatik Ade P'!E29 -> 3 | F28: ='6. Aritmatik Ade P'!#REF! -> #REF! | G28: =D28*E28*F28 -> #VALUE! | H28: =D28 -> BUKU | I28: =E28 -> 3 | J28: ='6. Aritmatik Ade P'!N29 -> 120000 | K28: =H28*I28*J28 -> #VALUE! | L28: =H28 -> BUKU | M28: =I28 -> 3 | N28: =F28 -> #REF! | O28: =L28*M28*N28 -> #VALUE!
C30: TOTAL B | G30: =SUM(G25:G29) -> #VALUE! | K30: =SUM(K25:K29) -> #VALUE! | O30: =SUM(O25:O28) -> #VALUE!
C31: TOTAL A + B | G31: =G30+G16 -> #VALUE! | K31: =K30+K16 -> #VALUE! | O31: =O30+O16 -> #VALUE!
C32: DIBULATKAN | G32: =ROUNDDOWN(G31,-3) -> #VALUE! | K32: =ROUNDDOWN(K31,-3) -> #VALUE! | O32: =ROUNDDOWN(O31,-3) -> #VALUE! | R32: =G32-O32 -> #VALUE!
C35: Konsultan Individual | K35: Pejabat Pengadaan Barang/Jasa,
C36: Pemantauan dan Evaluasi
C42: =C5 -> Ade Putra. ST. | K42: SUJOKO, ST
K43: NIP. 19680323 199703 1 002

Sheet 19. BA-Klari-Nego
B2: ='17. UND-Klari-Nego'!B1:K1 -> PEJABAT PENGADAAN BARANG/JASA PEMERINTAH
B3: ='17. UND-Klari-Nego'!B2:K2 -> PADA SATUAN KERJA PELAKSANAAN PRASARANA STRATEGIS RIAU
B4: ='17. UND-Klari-Nego'!B4:K4 -> TAHUN ANGGARAN 2025
B7: =[207]BaPby!B6 -> SATKER | I7: BERITA ACARA KLARIFIKASI DAN NEGOSIASI
B8: ='13. REKAP EVA'!E7 -> Satuan Kerja Pelaksanaan Prasarana Strategis Riau
B11: PEKERJAAN :
B12: ='14. BA - EVA'!B13 -> Konsultan Individual Team Leader | J12: Nomor | K12: : | L12: =jadwal!F22 -> 12.01/BA-KLARI-NEGO/PJB/KI-PRC/TL/PPK/PPS-RIAU/IV/2025
J13: Hari | K13: : | L13: Kamis
J14: Tanggal | K14: : | L14: =jadwal!H22 -> 11 April 2025
B15: LOKASI : | J15: Pagu | K15: : | L15: ='14. BA - EVA'!J15 -> 47700000
B16: ='14. BA - EVA'!B16:G16 -> Provinsi Riau
B19: Pada hari ini Rabu, tanggal Tiga puluh satu bulan Januari tahun Dua ribu delapan belas, yang bertanda tangan dibawah ini, Pejabat Pengadaan Pada Satker Perencanaan dan Pengendalian Program Infrastruktur Permukiman Tahun Anggaran 2018 yang diangkat sesuai dengan Surat Keputusan Kepala Satker Perencanaan dan Pengendalian Program Infrastruktur Permukiman, No : 06/KPTS/Cp/RDL/2018 tanggal 05 Januari 2018, mengambil tempat Ruang Rapat PPK Randal Riau Gedung PIP2B Jl. Arifin Ahmad Pekanbaru, telah melakukan Klarifikasi dan Negosiasi terhadap :
B25: I. | C25: Nama Konsultan Perorangan | F25: : | G25: ='16. pengumuman'!E19 -> Ade Putra. ST.
C26: Alamat | F26: : | G26: ='16. pengumuman'!E20 -> Jl. Berdikari Perum. Puri Alam Permai Blok A-6 Tenayan Raya Pekanbaru
C27: NPWP | F27: : | G27: ='16. pengumuman'!E21 -> 75.198.282.8-212.000
C28: Harga Penawaran | F28: : | G28: ='16. pengumuman'!E22 -> 47700000
C29: Harga Terkoreksi | F29: : | G29: ='16. pengumuman'!E23 -> 47700000
C30: Harga Setelah Negosiasi | F30: : | G30: ='18. Nego Arit Didi'!O32 -> #VALUE!
C31: Waktu Pelaksanaan | F31: : | G31: ='16. pengumuman'!E24 -> 3 (Tiga) Bulan
B33: II. | C33: Aspek teknis yang diklarifikasi untuk hasil pencapaian hasil kerja yang optimal meliputi :
E34: 1 Lingkup dan Sasaran jasa konsultansi
E35: 2 Cara Penanganan pekerjaan dan rencana kerja
E36: 3 Kualifikasi pemenang
E37: 4 Tata kerja pelaksanaan pekerjaan
E38: 5 Program alih pengetahuan
E39: 6 Jadwal pelaksanaan pekerjaan
E40: 7 Jadwal kerja pemenang
E41: 8 Fasilitas Penunjang
B43: Dari Hasil klarifikasi aspek teknis, Panitia berkesimpulan bahwa aspek teknis : Memenuhi Syarat / Tidak Memenuhi Syarat
B44: Alasan : ………………………………………………………………………………………………………………………………..
B46: III. | C46: Aspek Biaya yang perlu diklarifikasi dan di Negosiasi meliputi :
C47: a. | D47: Rekapitulasi Penawaran Biaya
C48: b. | D48: Volume kegiatan dan jenis pengeluaran
C49: c. | D49: Biaya satuan dibandingkan dengan biaya yang berlaku di pasaran
B51: Hasil Negosiasi adalah sebagai berikut :
B53: Harga Penawaran Semula | F53: : | G53: ='18. Nego Arit Didi'!K32 -> #VALUE!
G54: ='Terbilang versi 1'!B25 -> #VALUE!
B56: Harga Penawaran Terkoreksi | F56: : | G56: ='18. Nego Arit Didi'!K32 -> #VALUE!
G57: ='Terbilang versi 1'!B48 -> #VALUE!
B59: Harga Setelah Negosiasi | F59: : | G59: ='18. Nego Arit Didi'!O32 -> #VALUE!
...

Sheet Terbilang versi 1
B2: TERBILANG DENGAN RUPIAH | T2: TERBILANG ANGKA SAJA
B3: PEMENANG | C3: MILYAR | D3: JUTAAN | E3: RIBUAN | F3: SATUAN | G3: SEN | I3: 0 | U3: MILYAR | V3: JUTAAN | W3: RIBUAN | X3: SATUAN | Y3: SEN | AA3: 0
A4: PENAWARAN | B4: ='19. BA-Klari-Nego'!G53 -> #VALUE! | C4: =INT(B4/1000000000) -> #VALUE! | D4: =INT((B4-C4*1000000000)/1000000) -> #VALUE! | E4: =INT((B4-C4*1000000000-D4*1000000)/1000) -> #VALUE! | F4: =INT((B4-C4*1000000000-D4*1000000-E4*1000)) -> #VALUE! | G4: =ROUND(B4-INT(B4),2)*100 -> #VALUE! | I4: 1 | J4: =+L4 -> Satu | L4: Satu | R4: 1810668000 | T4: 19 | U4: =INT(T4/1000000000) -> 0 | V4: =INT((T4-U4*1000000000)/1000000) -> 0 | W4: =INT((T4-U4*1000000000-V4*1000000)/1000) -> 0 | X4: =INT((T4-U4*1000000000-V4*1000000-W4*1000)) -> 19 | Y4: =ROUND(T4-INT(T4),2)*100 -> 0 | AA4: 1 | AB4: =+AD4 -> Satu | AD4: Satu
I5: 2 | J5: =+L5 -> Dua | L5: Dua | AA5: 2 | AB5: =+AD5 -> Dua | AD5: Dua
B7: 1 | C7: =IF(C4>99,LEFT(C4,1),"0") -> #VALUE! | D7: =IF(D4>99,LEFT(D4,1),"0") -> #VALUE! | E7: =IF(E4>99,LEFT(E4,1),"0") -> #VALUE! | F7: =IF(F4>99,LEFT(F4,1),"0") -> #VALUE! | I7: 3 | J7: =+L7 -> Tiga | L7: Tiga | T7: 1 | U7: =IF(U4>99,LEFT(U4,1),"0") -> 0 | V7: =IF(V4>99,LEFT(V4,1),"0") -> 0 | W7: =IF(W4>99,LEFT(W4,1),"0") -> 0 | X7: =IF(X4>99,LEFT(X4,1),"0") -> 0 | AA7: 3 | AB7: =+AD7 -> Tiga | AD7: Tiga
B8: 2 | C8: =IF(C4>99,MID(C4,2,1),IF(C4>9,LEFT(C4,1),"0")) -> #VALUE! | D8: =IF(D4>99,MID(D4,2,1),IF(D4>9,LEFT(D4,1),"0")) -> #VALUE! | E8: =IF(E4>99,MID(E4,2,1),IF(E4>9,LEFT(E4,1),"0")) -> #VALUE! | F8: =IF(F4>99,MID(F4,2,1),IF(F4>9,LEFT(F4,1),"0")) -> #VALUE! | I8: 4 | J8: =+L8 -> Empat | L8: Empat | T8: 2 | U8: =IF(U4>99,MID(U4,2,1),IF(U4>9,LEFT(U4,1),"0")) -> 0 | V8: =IF(V4>99,MID(V4,2,1),IF(V4>9,LEFT(V4,1),"0")) -> 0 | W8: =IF(W4>99,MID(W4,2,1),IF(W4>9,LEFT(W4,1),"0")) -> 0 | X8: =IF(X4>99,MID(X4,2,1),IF(X4>9,LEFT(X4,1),"0")) -> 1 | AA8: 4 | AB8: =+AD8 -> Empat | AD8: Empat
B9: 3 | C9: =RIGHT(C4) -> #VALUE! | D9: =RIGHT(D4) -> #VALUE! | E9: =RIGHT(E4) -> #VALUE! | F9: =RIGHT(F4) -> #VALUE! | I9: 5 | J9: =+L9 -> Lima | L9: Lima | T9: 3 | U9: =RIGHT(U4) -> 0 | V9: =RIGHT(V4) -> 0 | W9: =RIGHT(W4) -> 0 | X9: =RIGHT(X4) -> 9 | AA9: 5 | AB9: =+AD9 -> Lima | AD9: Lima
I10: 6 | J10: =+L10 -> Enam | L10: Enam | AA10: 6 | AB10: =+AD10 -> Enam | AD10: Enam
B11: 1 | C11: =IF(C7="1","Seratus",IF(C7="0","",CONCATENATE(VLOOKUP(C7,angka,2)," Ratus"))) -> #VALUE! | D11: =IF(D7="1","Seratus",IF(D7="0","",CONCATENATE(VLOOKUP(D7,angka,2)," Ratus"))) -> #VALUE! | E11: =IF(E7="1","Seratus",IF(E7="0","",CONCATENATE(VLOOKUP(E7,angka,2)," Ratus"))) -> #VALUE! | F11: =IF(F7="1","Seratus",IF(F7="0","",CONCATENATE(VLOOKUP(F7,angka,2)," Ratus"))) -> #VALUE! | I11: 7 | J11: =+L11 -> Tujuh | L11: Tujuh | T11: 1 | U11: =IF(U7="1","Seratus",IF(U7="0","",CONCATENATE(VLOOKUP(U7,angka,2)," Ratus"))) | V11: =IF(V7="1","Seratus",IF(V7="0","",CONCATENATE(VLOOKUP(V7,angka,2)," Ratus"))) | W11: =IF(W7="1","Seratus",IF(W7="0","",CONCATENATE(VLOOKUP(W7,angka,2)," Ratus"))) | X11: =IF(X7="1","Seratus",IF(X7="0","",CONCATENATE(VLOOKUP(X7,angka,2)," Ratus"))) | AA11: 7 | AB11: =+AD11 -> Tujuh | AD11: Tujuh
C12: =VALUE(CONCATENATE(C8,C9)) -> #VALUE! | D12: =VALUE(CONCATENATE(D8,D9)) -> #VALUE! | E12: =VALUE(CONCATENATE(E8,E9)) -> #VALUE! | F12: =VALUE(CONCATENATE(F8,F9)) -> #VALUE! | I12: 8 | J12: =+L12 -> Delapan | L12: Delapan | U12: =VALUE(CONCATENATE(U8,U9)) -> 0 | V12: =VALUE(CONCATENATE(V8,V9)) -> 0 | W12: =VALUE(CONCATENATE(W8,W9)) -> 0 | X12: =VALUE(CONCATENATE(X8,X9)) -> 19 | AA12: 8 | AB12: =+AD12 -> Delapan | AD12: Delapan
B13: 2 | C13: =IF(AND(C12>9,C12<20),VLOOKUP(C12,angka,2),IF(C8="0","",CONCATENATE(VLOOKUP(C8,angka,2)," Puluh"))) -> #VALUE! | D13: =IF(AND(D12>9,D12<20),VLOOKUP(D12,angka,2),IF(D8="0","",CONCATENATE(VLOOKUP(D8,angka,2)," Puluh"))) -> #VALUE! | E13: =IF(AND(E12>9,E12<20),VLOOKUP(E12,angka,2),IF(E8="0","",CONCATENATE(VLOOKUP(E8,angka,2)," Puluh"))) -> #VALUE! | F13: =IF(AND(F12>9,F12<20),VLOOKUP(F12,angka,2),IF(F8="0","",CONCATENATE(VLOOKUP(F8,angka,2)," Puluh"))) -> #VALUE! | I13: 9 | J13: =+L13 -> Sembilan | L13: Sembilan | T13: 2 | U13: =IF(AND(U12>9,U12<20),VLOOKUP(U12,angka,2),IF(U8="0","",CONCATENATE(VLOOKUP(U8,angka,2)," Puluh"))) | V13: =IF(AND(V12>9,V12<20),VLOOKUP(V12,angka,2),IF(V8="0","",CONCATENATE(VLOOKUP(V8,angka,2)," Puluh"))) | W13: =IF(AND(W12>9,W12<20),VLOOKUP(W12,angka,2),IF(W8="0","",CONCATENATE(VLOOKUP(W8,angka,2)," Puluh"))) | X13: =IF(AND(X12>9,X12<20),VLOOKUP(X12,angka,2),IF(X8="0","",CONCATENATE(VLOOKUP(X8,angka,2)," Puluh"))) -> Sembilan Belas | AA13: 9 | AB13: =+AD13 -> Sembilan | AD13: Sembilan
B14: 3 | C14: =IF(AND(C12>9,C12<20),"",VLOOKUP(C9,angka,2)) -> #VALUE! | D14: =IF(AND(D12>9,D12<20),"",VLOOKUP(D9,angka,2)) -> #VALUE! | E14: =IF(AND(E12>9,E12<20),"",VLOOKUP(E9,angka,2)) -> #VALUE! | F14: =IF(AND(F12>9,F12<20),"",VLOOKUP(F9,angka,2)) -> #VALUE! | I14: 10 | J14: =+L14 -> Sepuluh | L14: Sepuluh | T14: 3 | U14: =IF(AND(U12>9,U12<20),"",VLOOKUP(U9,angka,2)) | V14: =IF(AND(V12>9,V12<20),"",VLOOKUP(V9,angka,2)) | W14: =IF(AND(W12>9,W12<20),"",VLOOKUP(W9,angka,2)) | X14: =IF(AND(X12>9,X12<20),"",VLOOKUP(X9,angka,2)) | AA14: 10 | AB14: =+AD14 -> Sepuluh | AD14: Sepuluh
I16: 11 | J16: =+L16 -> Sebelas | L16: Sebelas | AA16: 11 | AB16: =+AD16 -> Sebelas | AD16: Sebelas
C17: =IF(AND(C7="0",C12=0),"",CONCATENATE(C11," ",C13," ",C14," Milyar ")) -> #VALUE! | D17: =IF(AND(D7="0",D12=0)," ",CONCATENATE(D11," ",D13," ",D14," Juta ")) -> #VALUE! | E17: =IF(AND(E7="0",E12=0),"",CONCATENATE(E11," ",E13," ",E14," Ribu ")) -> #VALUE! | F17: =IF(AND(F7="0",F12=0),"",CONCATENATE(F11," ",F13," ",F14,)) -> #VALUE! | G17: =IF(G4=0,"",CONCATENATE(" ",G4,"/100 ")) -> #VALUE! | I17: 12 | J17: =+L17 -> Dua Belas | L17: Dua Belas | U17: =IF(AND(U7="0",U12=0),"",CONCATENATE(U11," ",U13," ",U14," Milyar ")) | V17: =IF(AND(V7="0",V12=0),"",CONCATENATE(V11," ",V13," ",V14," Juta ")) | W17: =IF(AND(W7="0",W12=0),"",CONCATENATE(W11," ",W13," ",W14," Ribu ")) | X17: =IF(AND(X7="0",X12=0),"",CONCATENATE(X11," ",X13," ",X14,)) -> Sembilan Belas | Y17: =IF(Y4=0,"",CONCATENATE(" ",Y4,"/100 ")) | AA17: 12 | AB17: =+AD17 -> Dua Belas | AD17: Dua Belas
I18: 13 | J18: =+L18 -> Tiga Belas | L18: Tiga Belas | AA18: 13 | AB18: =+AD18 -> Tiga Belas | AD18: Tiga Belas
